<?xml version="1.0" ?>
<!-- =================================================================================== -->
<!-- |    This document was autogenerated by xacro from dual_motoman_mh5.xacro         | -->
<!-- |    EDITING THIS FILE BY HAND IS NOT RECOMMENDED                                 | -->
<!-- =================================================================================== -->
<robot name="motoman_mh5" xmlns:xacro="http://ros.org/wiki/xacro">
  <link name="world"/>
  <!-- link list -->
  <link name="r1_base_link">
    <visual>
      <origin rpy="0 0 3.14159"/>
      <geometry>
        <mesh filename="package://motoman_mh5_support/meshes/mh5/visual/MH5_BASE_AXIS.stl"/>
      </geometry>
      <material name="blue">
        <color rgba="0 0 1 1"/>
      </material>
    </visual>
    <collision>
      <origin rpy="0 0 3.14159"/>
      <geometry>
        <mesh filename="package://motoman_mh5_support/meshes/mh5/collision/MH5_BASE_AXIS.stl"/>
      </geometry>
      <material name="yellow">
        <color rgba="0 1 1 1"/>
      </material>
    </collision>
  </link>
  <link name="r1_link_s">
    <visual>
      <geometry>
        <mesh filename="package://motoman_mh5_support/meshes/mh5/visual/MH5_S_AXIS.stl"/>
      </geometry>
      <material name="silver">
        <color rgba="0.8 0.8 0.8 1"/>
      </material>
    </visual>
    <collision>
      <geometry>
        <mesh filename="package://motoman_mh5_support/meshes/mh5/collision/MH5_S_AXIS.stl"/>
      </geometry>
      <material name="yellow"/>
    </collision>
  </link>
  <link name="r1_link_l">
    <visual>
      <!-- <origin rpy="1.57 3.1416 0" xyz="0 0 0"/> -->
      <geometry>
        <mesh filename="package://motoman_mh5_support/meshes/mh5/visual/MH5_L_AXIS.stl"/>
      </geometry>
      <material name="blue"/>
    </visual>
    <collision>
      <!-- <origin rpy="1.57 3.1416 0" xyz="0 0 0"/> -->
      <geometry>
        <mesh filename="package://motoman_mh5_support/meshes/mh5/collision/MH5_L_AXIS.stl"/>
      </geometry>
      <material name="yellow"/>
    </collision>
  </link>
  <link name="r1_link_u">
    <visual>
      <!-- <origin rpy="1.57 -3.1415 0" xyz="0 0 0"/> -->
      <geometry>
        <mesh filename="package://motoman_mh5_support/meshes/mh5/visual/MH5_U_AXIS.stl"/>
      </geometry>
      <material name="blue"/>
    </visual>
    <collision>
      <!-- <origin rpy="1.57 -3.1415 0" xyz="0 0 0"/> -->
      <geometry>
        <mesh filename="package://motoman_mh5_support/meshes/mh5/collision/MH5_U_AXIS.stl"/>
      </geometry>
      <material name="yellow"/>
    </collision>
  </link>
  <link name="r1_link_r">
    <visual>
      <!-- <origin rpy="0 0 3.1416" xyz="0 0 0"/> -->
      <geometry>
        <mesh filename="package://motoman_mh5_support/meshes/mh5/visual/MH5_R_AXIS.stl"/>
      </geometry>
      <material name="silver"/>
    </visual>
    <collision>
      <!-- <origin rpy="0 0 3.1416" xyz="0 0 0"/> -->
      <geometry>
        <mesh filename="package://motoman_mh5_support/meshes/mh5/collision/MH5_R_AXIS.stl"/>
      </geometry>
      <material name="yellow"/>
    </collision>
  </link>
  <link name="r1_link_b">
    <visual>
      <!-- <origin rpy="-1.57 0 3.1416" xyz="0 0 0"/> -->
      <geometry>
        <mesh filename="package://motoman_mh5_support/meshes/mh5/visual/MH5_B_AXIS.stl"/>
      </geometry>
      <material name="blue"/>
    </visual>
    <collision>
      <!-- <origin rpy="-1.57 0 3.1416" xyz="0 0 0"/> -->
      <geometry>
        <mesh filename="package://motoman_mh5_support/meshes/mh5/collision/MH5_B_AXIS.stl"/>
      </geometry>
      <material name="yellow"/>
    </collision>
  </link>
  <link name="r1_link_t">
    <visual>
      <geometry>
        <mesh filename="package://motoman_mh5_support/meshes/mh5/visual/MH5_T_AXIS.stl"/>
      </geometry>
      <material name="silver"/>
    </visual>
    <collision>
      <geometry>
        <mesh filename="package://motoman_mh5_support/meshes/mh5/collision/MH5_T_AXIS.stl"/>
      </geometry>
      <material name="yellow"/>
    </collision>
  </link>
  <!-- end of link list -->
  <!-- joint list -->
  <joint name="r1_joint_s" type="revolute">
    <parent link="r1_base_link"/>
    <child link="r1_link_s"/>
    <origin rpy="0 0 0" xyz="0 0 0.1990"/>
    <axis xyz="0 0 1"/>
    <limit effort="100" lower="-2.9671" upper="2.9671" velocity="2.96"/>
  </joint>
  <joint name="r1_joint_l" type="revolute">
    <parent link="r1_link_s"/>
    <child link="r1_link_l"/>
    <origin rpy="0 0 0" xyz="0.0880 0 0.1310"/>
    <axis xyz="0 1 0"/>
    <limit effort="100" lower="-1.1345" upper="2.6180" velocity="2.96"/>
  </joint>
  <joint name="r1_joint_u" type="revolute">
    <parent link="r1_link_l"/>
    <child link="r1_link_u"/>
    <origin rpy="0 0 0" xyz="0 0 0.3100"/>
    <axis xyz="0 -1 0"/>

    <limit effort="100" lower="-1.0122" upper="3.2218" velocity="2.96"/>
  </joint>
  <joint name="r1_joint_r" type="revolute">
    <parent link="r1_link_u"/>
    <child link="r1_link_r"/>
    <origin rpy="0 0 0" xyz="0.0715 0 0.0399"/>
    <axis xyz="-1 0 0"/>
    <limit effort="100" lower="-3.3161" upper="3.3161" velocity="3.48"/>
  </joint>
  <joint name="r1_joint_b" type="revolute">
    <parent link="r1_link_r"/>
    <child link="r1_link_b"/>
    <origin rpy="0 0 0" xyz="0.2335 0 0"/>
    <axis xyz="0 -1 0"/>
    <limit effort="100" lower="-2.1817" upper="2.1817" velocity="3.48"/>
  </joint>
  <joint name="r1_joint_t" type="revolute">
    <parent link="r1_link_b"/>
    <child link="r1_link_t"/>
    <origin rpy="0 0 0" xyz="0.0865 0 0"/>
    <axis xyz="-1 0 0"/>
    <limit effort="100" lower="-6.2831" upper="6.2831" velocity="6.97"/>
  </joint>
  <!-- end of joint list -->
  <!-- link list -->
  <link name="r2_base_link">
    <visual>
      <origin rpy="0 0 3.14159"/>
      <geometry>
        <mesh filename="package://motoman_mh5_support/meshes/mh5/visual/MH5_BASE_AXIS.stl"/>
      </geometry>
      <material name="blue">
        <color rgba="0 0 1 1"/>
      </material>
    </visual>
    <collision>
      <origin rpy="0 0 3.14159"/>
      <geometry>
        <mesh filename="package://motoman_mh5_support/meshes/mh5/collision/MH5_BASE_AXIS.stl"/>
      </geometry>
      <material name="yellow">
        <color rgba="0 1 1 1"/>
      </material>
    </collision>
  </link>
  <link name="r2_link_s">
    <visual>
      <geometry>
        <mesh filename="package://motoman_mh5_support/meshes/mh5/visual/MH5_S_AXIS.stl"/>
      </geometry>
      <material name="silver">
        <color rgba="0.8 0.8 0.8 1"/>
      </material>
    </visual>
    <collision>
      <geometry>
        <mesh filename="package://motoman_mh5_support/meshes/mh5/collision/MH5_S_AXIS.stl"/>
      </geometry>
      <material name="yellow"/>
    </collision>
  </link>
  <link name="r2_link_l">
    <visual>
      <!-- <origin rpy="1.57 3.1416 0" xyz="0 0 0"/> -->
      <geometry>
        <mesh filename="package://motoman_mh5_support/meshes/mh5/visual/MH5_L_AXIS.stl"/>
      </geometry>
      <material name="blue"/>
    </visual>
    <collision>
      <!-- <origin rpy="1.57 3.1416 0" xyz="0 0 0"/> -->
      <geometry>
        <mesh filename="package://motoman_mh5_support/meshes/mh5/collision/MH5_L_AXIS.stl"/>
      </geometry>
      <material name="yellow"/>
    </collision>
  </link>
  <link name="r2_link_u">
    <visual>
      <!-- <origin rpy="1.57 -3.1415 0" xyz="0 0 0"/> -->
      <geometry>
        <mesh filename="package://motoman_mh5_support/meshes/mh5/visual/MH5_U_AXIS.stl"/>
      </geometry>
      <material name="blue"/>
    </visual>
    <collision>
      <!-- <origin rpy="1.57 -3.1415 0" xyz="0 0 0"/> -->
      <geometry>
        <mesh filename="package://motoman_mh5_support/meshes/mh5/collision/MH5_U_AXIS.stl"/>
      </geometry>
      <material name="yellow"/>
    </collision>
  </link>
  <link name="r2_link_r">
    <visual>
      <!-- <origin rpy="0 0 3.1416" xyz="0 0 0"/> -->
      <geometry>
        <mesh filename="package://motoman_mh5_support/meshes/mh5/visual/MH5_R_AXIS.stl"/>
      </geometry>
      <material name="silver"/>
    </visual>
    <collision>
      <!-- <origin rpy="0 0 3.1416" xyz="0 0 0"/> -->
      <geometry>
        <mesh filename="package://motoman_mh5_support/meshes/mh5/collision/MH5_R_AXIS.stl"/>
      </geometry>
      <material name="yellow"/>
    </collision>
  </link>
  <link name="r2_link_b">
    <visual>
      <!-- <origin rpy="-1.57 0 3.1416" xyz="0 0 0"/> -->
      <geometry>
        <mesh filename="package://motoman_mh5_support/meshes/mh5/visual/MH5_B_AXIS.stl"/>
      </geometry>
      <material name="blue"/>
    </visual>
    <collision>
      <!-- <origin rpy="-1.57 0 3.1416" xyz="0 0 0"/> -->
      <geometry>
        <mesh filename="package://motoman_mh5_support/meshes/mh5/collision/MH5_B_AXIS.stl"/>
      </geometry>
      <material name="yellow"/>
    </collision>
  </link>
  <link name="r2_link_t">
    <visual>
      <geometry>
        <mesh filename="package://motoman_mh5_support/meshes/mh5/visual/MH5_T_AXIS.stl"/>
      </geometry>
      <material name="silver"/>
    </visual>
    <collision>
      <geometry>
        <mesh filename="package://motoman_mh5_support/meshes/mh5/collision/MH5_T_AXIS.stl"/>
      </geometry>
      <material name="yellow"/>
    </collision>
  </link>
  <!-- end of link list -->
  <!-- joint list -->
  <joint name="r2_joint_s" type="revolute">
    <parent link="r2_base_link"/>
    <child link="r2_link_s"/>
    <origin rpy="0 0 0" xyz="0 0 0.1990"/>
    <axis xyz="0 0 1"/>
    <limit effort="100" lower="-2.9671" upper="2.9671" velocity="2.96"/>
  </joint>
  <joint name="r2_joint_l" type="revolute">
    <parent link="r2_link_s"/>
    <child link="r2_link_l"/>
    <origin rpy="0 0 0" xyz="0.0880 0 0.1310"/>
    <axis xyz="0 1 0"/>
    <limit effort="100" lower="-1.1345" upper="2.6180" velocity="2.96"/>
  </joint>
  <joint name="r2_joint_u" type="revolute">
    <parent link="r2_link_l"/>
    <child link="r2_link_u"/>
    <origin rpy="0 0 0" xyz="0 0 0.3100"/>
    <axis xyz="0 -1 0"/>

    <limit effort="100" lower="-1.0122" upper="3.2218" velocity="2.96"/>
  </joint>
  <joint name="r2_joint_r" type="revolute">
    <parent link="r2_link_u"/>
    <child link="r2_link_r"/>
    <origin rpy="0 0 0" xyz="0.0715 0 0.0399"/>
    <axis xyz="-1 0 0"/>
    <limit effort="100" lower="-3.3161" upper="3.3161" velocity="3.48"/>
  </joint>
  <joint name="r2_joint_b" type="revolute">
    <parent link="r2_link_r"/>
    <child link="r2_link_b"/>
    <origin rpy="0 0 0" xyz="0.2335 0 0"/>
    <axis xyz="0 -1 0"/>
    <limit effort="100" lower="-2.1817" upper="2.1817" velocity="3.48"/>
  </joint>
  <joint name="r2_joint_t" type="revolute">
    <parent link="r2_link_b"/>
    <child link="r2_link_t"/>
    <origin rpy="0 0 0" xyz="0.0865 0 0"/>
    <axis xyz="-1 0 0"/>
    <limit effort="100" lower="-6.2831" upper="6.2831" velocity="6.97"/>
  </joint>
  <!-- end of joint list -->
  <joint name="world_r1_robot_joint" type="fixed">
    <parent link="world"/>
    <child link="r1_base_link"/>
    <origin rpy="0.0 0.0 0.0" xyz="0.0 0.0 0.0"/>
  </joint>
  <joint name="world_r2_robot_joint" type="fixed">
    <parent link="world"/>
    <child link="r2_base_link"/>
    <origin rpy="0.0 0.0 3.1415926" xyz="1.2 0.0 0.0"/>
  </joint>
</robot>

